{
 "cells": [
  {
   "cell_type": "code",
   "execution_count": 50,
   "id": "e59467fe",
   "metadata": {},
   "outputs": [],
   "source": [
    "import pandas as pd\n",
    "import numpy as np\n",
    "from collections import Counter\n",
    "import math\n"
   ]
  },
  {
   "cell_type": "code",
   "execution_count": 51,
   "id": "8707edb6",
   "metadata": {},
   "outputs": [],
   "source": [
    "import pandas as pd\n",
    "from scipy.io import arff\n",
    "\n",
    "# Especifica la ruta y el nombre del archivo ARFF\n",
    "archivo_arff = 'd:/dataset/cpu.arff'\n",
    "\n",
    "# Carga el archivo ARFF utilizando la función loadarff de scipy.io\n",
    "datos, meta = arff.loadarff(archivo_arff)\n",
    "\n",
    "# Convierte los datos ARFF a un DataFrame de pandas\n",
    "df = pd.DataFrame(datos)\n",
    "\n",
    "# Especifica la ruta y el nombre del archivo CSV de salida\n",
    "archivo_csv = 'd:/dataset/archivocpu.csv'\n",
    "\n",
    "# Guarda el DataFrame en formato CSV\n",
    "df.to_csv(archivo_csv, index=False)"
   ]
  },
  {
   "cell_type": "code",
   "execution_count": 52,
   "id": "0c16cded",
   "metadata": {},
   "outputs": [],
   "source": [
    "##lee el archivo\n",
    "archivo_csv = 'd:/dataset/archivocpu.csv'\n",
    "datos = pd.read_csv(archivo_csv)"
   ]
  },
  {
   "cell_type": "code",
   "execution_count": 53,
   "id": "e23de526",
   "metadata": {},
   "outputs": [
    {
     "name": "stdout",
     "output_type": "stream",
     "text": [
      "      MYCT    MMIN     MMAX   CACH  CHMIN  CHMAX  class\n",
      "0    125.0   256.0   6000.0  256.0   16.0  128.0  198.0\n",
      "1     29.0  8000.0  32000.0   32.0    8.0   32.0  269.0\n",
      "2     29.0  8000.0  32000.0   32.0    8.0   32.0  220.0\n",
      "3     29.0  8000.0  32000.0   32.0    8.0   32.0  172.0\n",
      "4     29.0  8000.0  16000.0   32.0    8.0   16.0  132.0\n",
      "..     ...     ...      ...    ...    ...    ...    ...\n",
      "204  124.0  1000.0   8000.0    0.0    1.0    8.0   42.0\n",
      "205   98.0  1000.0   8000.0   32.0    2.0    8.0   46.0\n",
      "206  125.0  2000.0   8000.0    0.0    2.0   14.0   52.0\n",
      "207  480.0   512.0   8000.0   32.0    0.0    0.0   67.0\n",
      "208  480.0  1000.0   4000.0    0.0    0.0    0.0   45.0\n",
      "\n",
      "[209 rows x 7 columns]\n"
     ]
    }
   ],
   "source": [
    "print(datos)"
   ]
  },
  {
   "cell_type": "markdown",
   "id": "e3a47243",
   "metadata": {},
   "source": [
    "Divide los datos en características (X) y etiquetas (y):"
   ]
  },
  {
   "cell_type": "code",
   "execution_count": 54,
   "id": "058fdd22",
   "metadata": {},
   "outputs": [],
   "source": [
    "X = datos.drop('class', axis=1)  \n",
    "y = datos['class']"
   ]
  },
  {
   "cell_type": "markdown",
   "id": "917c02d7",
   "metadata": {},
   "source": [
    "conjunto de entrenamiento\n"
   ]
  },
  {
   "cell_type": "code",
   "execution_count": 61,
   "id": "6605788a",
   "metadata": {},
   "outputs": [],
   "source": [
    "from sklearn.model_selection import train_test_split\n",
    "\n",
    "\n",
    "\n",
    "X_entrenamiento, X_prueba, y_entrenamiento, y_prueba = train_test_split(X, y, test_size=0.2, random_state=42)\n"
   ]
  },
  {
   "cell_type": "markdown",
   "id": "821e14d2",
   "metadata": {},
   "source": [
    "#Preprocesa los datos según sea necesario (normalización, codificación one-hot, etc.).\n",
    "#Crea y entrena tu modelo de red neuronal con TensorFlow:"
   ]
  },
  {
   "cell_type": "code",
   "execution_count": 63,
   "id": "7b1925e9",
   "metadata": {},
   "outputs": [],
   "source": [
    "from sklearn.preprocessing import LabelEncoder\n",
    "from tensorflow.keras.utils import to_categorical\n",
    "\n",
    "# Codificar las etiquetas como enteros\n",
    "le = LabelEncoder()\n",
    "y_encoded = le.fit_transform(y)\n",
    "\n",
    "# Convertir las etiquetas codificadas a one-hot encoding\n",
    "y_one_hot = to_categorical(y_encoded)"
   ]
  },
  {
   "cell_type": "code",
   "execution_count": 64,
   "id": "a716c570",
   "metadata": {},
   "outputs": [
    {
     "name": "stdout",
     "output_type": "stream",
     "text": [
      "Epoch 1/10\n"
     ]
    },
    {
     "name": "stderr",
     "output_type": "stream",
     "text": [
      "C:\\Users\\Progra\\AppData\\Roaming\\Python\\Python39\\site-packages\\keras\\backend.py:5612: UserWarning: \"`sparse_categorical_crossentropy` received `from_logits=True`, but the `output` argument was produced by a Softmax activation and thus does not represent logits. Was this intended?\n",
      "  output, from_logits = _get_logits(\n"
     ]
    },
    {
     "ename": "InvalidArgumentError",
     "evalue": "Graph execution error:\n\nDetected at node 'sparse_categorical_crossentropy/SparseSoftmaxCrossEntropyWithLogits/SparseSoftmaxCrossEntropyWithLogits' defined at (most recent call last):\n    File \"C:\\ProgramData\\Anaconda3\\lib\\runpy.py\", line 197, in _run_module_as_main\n      return _run_code(code, main_globals, None,\n    File \"C:\\ProgramData\\Anaconda3\\lib\\runpy.py\", line 87, in _run_code\n      exec(code, run_globals)\n    File \"C:\\ProgramData\\Anaconda3\\lib\\site-packages\\ipykernel_launcher.py\", line 17, in <module>\n      app.launch_new_instance()\n    File \"C:\\ProgramData\\Anaconda3\\lib\\site-packages\\traitlets\\config\\application.py\", line 992, in launch_instance\n      app.start()\n    File \"C:\\ProgramData\\Anaconda3\\lib\\site-packages\\ipykernel\\kernelapp.py\", line 711, in start\n      self.io_loop.start()\n    File \"C:\\ProgramData\\Anaconda3\\lib\\site-packages\\tornado\\platform\\asyncio.py\", line 215, in start\n      self.asyncio_loop.run_forever()\n    File \"C:\\ProgramData\\Anaconda3\\lib\\asyncio\\base_events.py\", line 601, in run_forever\n      self._run_once()\n    File \"C:\\ProgramData\\Anaconda3\\lib\\asyncio\\base_events.py\", line 1905, in _run_once\n      handle._run()\n    File \"C:\\ProgramData\\Anaconda3\\lib\\asyncio\\events.py\", line 80, in _run\n      self._context.run(self._callback, *self._args)\n    File \"C:\\ProgramData\\Anaconda3\\lib\\site-packages\\ipykernel\\kernelbase.py\", line 510, in dispatch_queue\n      await self.process_one()\n    File \"C:\\ProgramData\\Anaconda3\\lib\\site-packages\\ipykernel\\kernelbase.py\", line 499, in process_one\n      await dispatch(*args)\n    File \"C:\\ProgramData\\Anaconda3\\lib\\site-packages\\ipykernel\\kernelbase.py\", line 406, in dispatch_shell\n      await result\n    File \"C:\\ProgramData\\Anaconda3\\lib\\site-packages\\ipykernel\\kernelbase.py\", line 729, in execute_request\n      reply_content = await reply_content\n    File \"C:\\ProgramData\\Anaconda3\\lib\\site-packages\\ipykernel\\ipkernel.py\", line 411, in do_execute\n      res = shell.run_cell(\n    File \"C:\\ProgramData\\Anaconda3\\lib\\site-packages\\ipykernel\\zmqshell.py\", line 531, in run_cell\n      return super().run_cell(*args, **kwargs)\n    File \"C:\\ProgramData\\Anaconda3\\lib\\site-packages\\IPython\\core\\interactiveshell.py\", line 3006, in run_cell\n      result = self._run_cell(\n    File \"C:\\ProgramData\\Anaconda3\\lib\\site-packages\\IPython\\core\\interactiveshell.py\", line 3061, in _run_cell\n      result = runner(coro)\n    File \"C:\\ProgramData\\Anaconda3\\lib\\site-packages\\IPython\\core\\async_helpers.py\", line 129, in _pseudo_sync_runner\n      coro.send(None)\n    File \"C:\\ProgramData\\Anaconda3\\lib\\site-packages\\IPython\\core\\interactiveshell.py\", line 3266, in run_cell_async\n      has_raised = await self.run_ast_nodes(code_ast.body, cell_name,\n    File \"C:\\ProgramData\\Anaconda3\\lib\\site-packages\\IPython\\core\\interactiveshell.py\", line 3445, in run_ast_nodes\n      if await self.run_code(code, result, async_=asy):\n    File \"C:\\ProgramData\\Anaconda3\\lib\\site-packages\\IPython\\core\\interactiveshell.py\", line 3505, in run_code\n      exec(code_obj, self.user_global_ns, self.user_ns)\n    File \"C:\\Users\\Progra\\AppData\\Local\\Temp\\ipykernel_12132\\1212032126.py\", line 14, in <module>\n      modelo.fit(X_entrenamiento, y_entrenamiento, epochs=10)\n    File \"C:\\Users\\Progra\\AppData\\Roaming\\Python\\Python39\\site-packages\\keras\\utils\\traceback_utils.py\", line 65, in error_handler\n      return fn(*args, **kwargs)\n    File \"C:\\Users\\Progra\\AppData\\Roaming\\Python\\Python39\\site-packages\\keras\\engine\\training.py\", line 1685, in fit\n      tmp_logs = self.train_function(iterator)\n    File \"C:\\Users\\Progra\\AppData\\Roaming\\Python\\Python39\\site-packages\\keras\\engine\\training.py\", line 1284, in train_function\n      return step_function(self, iterator)\n    File \"C:\\Users\\Progra\\AppData\\Roaming\\Python\\Python39\\site-packages\\keras\\engine\\training.py\", line 1268, in step_function\n      outputs = model.distribute_strategy.run(run_step, args=(data,))\n    File \"C:\\Users\\Progra\\AppData\\Roaming\\Python\\Python39\\site-packages\\keras\\engine\\training.py\", line 1249, in run_step\n      outputs = model.train_step(data)\n    File \"C:\\Users\\Progra\\AppData\\Roaming\\Python\\Python39\\site-packages\\keras\\engine\\training.py\", line 1051, in train_step\n      loss = self.compute_loss(x, y, y_pred, sample_weight)\n    File \"C:\\Users\\Progra\\AppData\\Roaming\\Python\\Python39\\site-packages\\keras\\engine\\training.py\", line 1109, in compute_loss\n      return self.compiled_loss(\n    File \"C:\\Users\\Progra\\AppData\\Roaming\\Python\\Python39\\site-packages\\keras\\engine\\compile_utils.py\", line 265, in __call__\n      loss_value = loss_obj(y_t, y_p, sample_weight=sw)\n    File \"C:\\Users\\Progra\\AppData\\Roaming\\Python\\Python39\\site-packages\\keras\\losses.py\", line 142, in __call__\n      losses = call_fn(y_true, y_pred)\n    File \"C:\\Users\\Progra\\AppData\\Roaming\\Python\\Python39\\site-packages\\keras\\losses.py\", line 268, in call\n      return ag_fn(y_true, y_pred, **self._fn_kwargs)\n    File \"C:\\Users\\Progra\\AppData\\Roaming\\Python\\Python39\\site-packages\\keras\\losses.py\", line 2078, in sparse_categorical_crossentropy\n      return backend.sparse_categorical_crossentropy(\n    File \"C:\\Users\\Progra\\AppData\\Roaming\\Python\\Python39\\site-packages\\keras\\backend.py\", line 5660, in sparse_categorical_crossentropy\n      res = tf.nn.sparse_softmax_cross_entropy_with_logits(\nNode: 'sparse_categorical_crossentropy/SparseSoftmaxCrossEntropyWithLogits/SparseSoftmaxCrossEntropyWithLogits'\nReceived a label value of 277 which is outside the valid range of [0, 3).  Label values: 53 188 76 20 37 22 25 16 40 113 14 36 12 32 35 27 22 100 277 20 214 24 29 66 237 7 64 76 32 46 143 32\n\t [[{{node sparse_categorical_crossentropy/SparseSoftmaxCrossEntropyWithLogits/SparseSoftmaxCrossEntropyWithLogits}}]] [Op:__inference_train_function_10151]",
     "output_type": "error",
     "traceback": [
      "\u001b[1;31m---------------------------------------------------------------------------\u001b[0m",
      "\u001b[1;31mInvalidArgumentError\u001b[0m                      Traceback (most recent call last)",
      "Cell \u001b[1;32mIn[64], line 14\u001b[0m\n\u001b[0;32m     11\u001b[0m \u001b[38;5;66;03m#modelo.compile(optimizer='adam', loss='sparse_categorical_crossentropy', metrics=['accuracy'])\u001b[39;00m\n\u001b[0;32m     12\u001b[0m modelo\u001b[38;5;241m.\u001b[39mcompile(optimizer\u001b[38;5;241m=\u001b[39m\u001b[38;5;124m'\u001b[39m\u001b[38;5;124madam\u001b[39m\u001b[38;5;124m'\u001b[39m,loss \u001b[38;5;241m=\u001b[39m tf\u001b[38;5;241m.\u001b[39mkeras\u001b[38;5;241m.\u001b[39mlosses\u001b[38;5;241m.\u001b[39mSparseCategoricalCrossentropy(from_logits\u001b[38;5;241m=\u001b[39m\u001b[38;5;28;01mTrue\u001b[39;00m), metrics\u001b[38;5;241m=\u001b[39m[\u001b[38;5;124m'\u001b[39m\u001b[38;5;124maccuracy\u001b[39m\u001b[38;5;124m'\u001b[39m])\n\u001b[1;32m---> 14\u001b[0m \u001b[43mmodelo\u001b[49m\u001b[38;5;241;43m.\u001b[39;49m\u001b[43mfit\u001b[49m\u001b[43m(\u001b[49m\u001b[43mX_entrenamiento\u001b[49m\u001b[43m,\u001b[49m\u001b[43m \u001b[49m\u001b[43my_entrenamiento\u001b[49m\u001b[43m,\u001b[49m\u001b[43m \u001b[49m\u001b[43mepochs\u001b[49m\u001b[38;5;241;43m=\u001b[39;49m\u001b[38;5;241;43m10\u001b[39;49m\u001b[43m)\u001b[49m\n",
      "File \u001b[1;32m~\\AppData\\Roaming\\Python\\Python39\\site-packages\\keras\\utils\\traceback_utils.py:70\u001b[0m, in \u001b[0;36mfilter_traceback.<locals>.error_handler\u001b[1;34m(*args, **kwargs)\u001b[0m\n\u001b[0;32m     67\u001b[0m     filtered_tb \u001b[38;5;241m=\u001b[39m _process_traceback_frames(e\u001b[38;5;241m.\u001b[39m__traceback__)\n\u001b[0;32m     68\u001b[0m     \u001b[38;5;66;03m# To get the full stack trace, call:\u001b[39;00m\n\u001b[0;32m     69\u001b[0m     \u001b[38;5;66;03m# `tf.debugging.disable_traceback_filtering()`\u001b[39;00m\n\u001b[1;32m---> 70\u001b[0m     \u001b[38;5;28;01mraise\u001b[39;00m e\u001b[38;5;241m.\u001b[39mwith_traceback(filtered_tb) \u001b[38;5;28;01mfrom\u001b[39;00m \u001b[38;5;28;01mNone\u001b[39;00m\n\u001b[0;32m     71\u001b[0m \u001b[38;5;28;01mfinally\u001b[39;00m:\n\u001b[0;32m     72\u001b[0m     \u001b[38;5;28;01mdel\u001b[39;00m filtered_tb\n",
      "File \u001b[1;32m~\\AppData\\Roaming\\Python\\Python39\\site-packages\\tensorflow\\python\\eager\\execute.py:52\u001b[0m, in \u001b[0;36mquick_execute\u001b[1;34m(op_name, num_outputs, inputs, attrs, ctx, name)\u001b[0m\n\u001b[0;32m     50\u001b[0m \u001b[38;5;28;01mtry\u001b[39;00m:\n\u001b[0;32m     51\u001b[0m   ctx\u001b[38;5;241m.\u001b[39mensure_initialized()\n\u001b[1;32m---> 52\u001b[0m   tensors \u001b[38;5;241m=\u001b[39m pywrap_tfe\u001b[38;5;241m.\u001b[39mTFE_Py_Execute(ctx\u001b[38;5;241m.\u001b[39m_handle, device_name, op_name,\n\u001b[0;32m     53\u001b[0m                                       inputs, attrs, num_outputs)\n\u001b[0;32m     54\u001b[0m \u001b[38;5;28;01mexcept\u001b[39;00m core\u001b[38;5;241m.\u001b[39m_NotOkStatusException \u001b[38;5;28;01mas\u001b[39;00m e:\n\u001b[0;32m     55\u001b[0m   \u001b[38;5;28;01mif\u001b[39;00m name \u001b[38;5;129;01mis\u001b[39;00m \u001b[38;5;129;01mnot\u001b[39;00m \u001b[38;5;28;01mNone\u001b[39;00m:\n",
      "\u001b[1;31mInvalidArgumentError\u001b[0m: Graph execution error:\n\nDetected at node 'sparse_categorical_crossentropy/SparseSoftmaxCrossEntropyWithLogits/SparseSoftmaxCrossEntropyWithLogits' defined at (most recent call last):\n    File \"C:\\ProgramData\\Anaconda3\\lib\\runpy.py\", line 197, in _run_module_as_main\n      return _run_code(code, main_globals, None,\n    File \"C:\\ProgramData\\Anaconda3\\lib\\runpy.py\", line 87, in _run_code\n      exec(code, run_globals)\n    File \"C:\\ProgramData\\Anaconda3\\lib\\site-packages\\ipykernel_launcher.py\", line 17, in <module>\n      app.launch_new_instance()\n    File \"C:\\ProgramData\\Anaconda3\\lib\\site-packages\\traitlets\\config\\application.py\", line 992, in launch_instance\n      app.start()\n    File \"C:\\ProgramData\\Anaconda3\\lib\\site-packages\\ipykernel\\kernelapp.py\", line 711, in start\n      self.io_loop.start()\n    File \"C:\\ProgramData\\Anaconda3\\lib\\site-packages\\tornado\\platform\\asyncio.py\", line 215, in start\n      self.asyncio_loop.run_forever()\n    File \"C:\\ProgramData\\Anaconda3\\lib\\asyncio\\base_events.py\", line 601, in run_forever\n      self._run_once()\n    File \"C:\\ProgramData\\Anaconda3\\lib\\asyncio\\base_events.py\", line 1905, in _run_once\n      handle._run()\n    File \"C:\\ProgramData\\Anaconda3\\lib\\asyncio\\events.py\", line 80, in _run\n      self._context.run(self._callback, *self._args)\n    File \"C:\\ProgramData\\Anaconda3\\lib\\site-packages\\ipykernel\\kernelbase.py\", line 510, in dispatch_queue\n      await self.process_one()\n    File \"C:\\ProgramData\\Anaconda3\\lib\\site-packages\\ipykernel\\kernelbase.py\", line 499, in process_one\n      await dispatch(*args)\n    File \"C:\\ProgramData\\Anaconda3\\lib\\site-packages\\ipykernel\\kernelbase.py\", line 406, in dispatch_shell\n      await result\n    File \"C:\\ProgramData\\Anaconda3\\lib\\site-packages\\ipykernel\\kernelbase.py\", line 729, in execute_request\n      reply_content = await reply_content\n    File \"C:\\ProgramData\\Anaconda3\\lib\\site-packages\\ipykernel\\ipkernel.py\", line 411, in do_execute\n      res = shell.run_cell(\n    File \"C:\\ProgramData\\Anaconda3\\lib\\site-packages\\ipykernel\\zmqshell.py\", line 531, in run_cell\n      return super().run_cell(*args, **kwargs)\n    File \"C:\\ProgramData\\Anaconda3\\lib\\site-packages\\IPython\\core\\interactiveshell.py\", line 3006, in run_cell\n      result = self._run_cell(\n    File \"C:\\ProgramData\\Anaconda3\\lib\\site-packages\\IPython\\core\\interactiveshell.py\", line 3061, in _run_cell\n      result = runner(coro)\n    File \"C:\\ProgramData\\Anaconda3\\lib\\site-packages\\IPython\\core\\async_helpers.py\", line 129, in _pseudo_sync_runner\n      coro.send(None)\n    File \"C:\\ProgramData\\Anaconda3\\lib\\site-packages\\IPython\\core\\interactiveshell.py\", line 3266, in run_cell_async\n      has_raised = await self.run_ast_nodes(code_ast.body, cell_name,\n    File \"C:\\ProgramData\\Anaconda3\\lib\\site-packages\\IPython\\core\\interactiveshell.py\", line 3445, in run_ast_nodes\n      if await self.run_code(code, result, async_=asy):\n    File \"C:\\ProgramData\\Anaconda3\\lib\\site-packages\\IPython\\core\\interactiveshell.py\", line 3505, in run_code\n      exec(code_obj, self.user_global_ns, self.user_ns)\n    File \"C:\\Users\\Progra\\AppData\\Local\\Temp\\ipykernel_12132\\1212032126.py\", line 14, in <module>\n      modelo.fit(X_entrenamiento, y_entrenamiento, epochs=10)\n    File \"C:\\Users\\Progra\\AppData\\Roaming\\Python\\Python39\\site-packages\\keras\\utils\\traceback_utils.py\", line 65, in error_handler\n      return fn(*args, **kwargs)\n    File \"C:\\Users\\Progra\\AppData\\Roaming\\Python\\Python39\\site-packages\\keras\\engine\\training.py\", line 1685, in fit\n      tmp_logs = self.train_function(iterator)\n    File \"C:\\Users\\Progra\\AppData\\Roaming\\Python\\Python39\\site-packages\\keras\\engine\\training.py\", line 1284, in train_function\n      return step_function(self, iterator)\n    File \"C:\\Users\\Progra\\AppData\\Roaming\\Python\\Python39\\site-packages\\keras\\engine\\training.py\", line 1268, in step_function\n      outputs = model.distribute_strategy.run(run_step, args=(data,))\n    File \"C:\\Users\\Progra\\AppData\\Roaming\\Python\\Python39\\site-packages\\keras\\engine\\training.py\", line 1249, in run_step\n      outputs = model.train_step(data)\n    File \"C:\\Users\\Progra\\AppData\\Roaming\\Python\\Python39\\site-packages\\keras\\engine\\training.py\", line 1051, in train_step\n      loss = self.compute_loss(x, y, y_pred, sample_weight)\n    File \"C:\\Users\\Progra\\AppData\\Roaming\\Python\\Python39\\site-packages\\keras\\engine\\training.py\", line 1109, in compute_loss\n      return self.compiled_loss(\n    File \"C:\\Users\\Progra\\AppData\\Roaming\\Python\\Python39\\site-packages\\keras\\engine\\compile_utils.py\", line 265, in __call__\n      loss_value = loss_obj(y_t, y_p, sample_weight=sw)\n    File \"C:\\Users\\Progra\\AppData\\Roaming\\Python\\Python39\\site-packages\\keras\\losses.py\", line 142, in __call__\n      losses = call_fn(y_true, y_pred)\n    File \"C:\\Users\\Progra\\AppData\\Roaming\\Python\\Python39\\site-packages\\keras\\losses.py\", line 268, in call\n      return ag_fn(y_true, y_pred, **self._fn_kwargs)\n    File \"C:\\Users\\Progra\\AppData\\Roaming\\Python\\Python39\\site-packages\\keras\\losses.py\", line 2078, in sparse_categorical_crossentropy\n      return backend.sparse_categorical_crossentropy(\n    File \"C:\\Users\\Progra\\AppData\\Roaming\\Python\\Python39\\site-packages\\keras\\backend.py\", line 5660, in sparse_categorical_crossentropy\n      res = tf.nn.sparse_softmax_cross_entropy_with_logits(\nNode: 'sparse_categorical_crossentropy/SparseSoftmaxCrossEntropyWithLogits/SparseSoftmaxCrossEntropyWithLogits'\nReceived a label value of 277 which is outside the valid range of [0, 3).  Label values: 53 188 76 20 37 22 25 16 40 113 14 36 12 32 35 27 22 100 277 20 214 24 29 66 237 7 64 76 32 46 143 32\n\t [[{{node sparse_categorical_crossentropy/SparseSoftmaxCrossEntropyWithLogits/SparseSoftmaxCrossEntropyWithLogits}}]] [Op:__inference_train_function_10151]"
     ]
    }
   ],
   "source": [
    "import tensorflow as tf\n",
    "modelo = tf.keras.models.Sequential([\n",
    "   tf.keras.layers.Input(shape=X_entrenamiento.shape[1:]),\n",
    "        tf.keras.layers.Dense(1000, activation='relu'),\n",
    "        tf.keras.layers.Dense(500, activation='relu',),\n",
    "        tf.keras.layers.Dense(300, activation='relu'),\n",
    "        tf.keras.layers.Dropout(0.2),\n",
    "        tf.keras.layers.Dense(3, activation='softmax')\n",
    "   # tf.keras.layers.Dense(units=1, activation='sigmoid')\n",
    "])\n",
    "#modelo.compile(optimizer='adam', loss='sparse_categorical_crossentropy', metrics=['accuracy'])\n",
    "modelo.compile(optimizer='adam',loss = tf.keras.losses.SparseCategoricalCrossentropy(from_logits=True), metrics=['accuracy'])\n",
    "\n",
    "modelo.fit(X_entrenamiento, y_entrenamiento, epochs=10)\n"
   ]
  },
  {
   "cell_type": "code",
   "execution_count": 57,
   "id": "aa3cb874",
   "metadata": {},
   "outputs": [
    {
     "name": "stdout",
     "output_type": "stream",
     "text": [
      "2/2 [==============================] - 0s 8ms/step\n"
     ]
    }
   ],
   "source": [
    "#realiza las prediciones\n",
    "predicciones = modelo.predict(X_prueba)\n"
   ]
  },
  {
   "cell_type": "code",
   "execution_count": 59,
   "id": "aa9b7b15",
   "metadata": {},
   "outputs": [],
   "source": [
    "from sklearn.metrics import confusion_matrix\n",
    "matriz_confusion = confusion_matrix(y_prueba, predicciones.argmax(axis=1))\n"
   ]
  },
  {
   "cell_type": "code",
   "execution_count": 60,
   "id": "2c2a7c7b",
   "metadata": {},
   "outputs": [
    {
     "name": "stderr",
     "output_type": "stream",
     "text": [
      "C:\\Users\\Progra\\AppData\\Roaming\\Python\\Python39\\site-packages\\keras\\backend.py:5612: UserWarning: \"`sparse_categorical_crossentropy` received `from_logits=True`, but the `output` argument was produced by a Softmax activation and thus does not represent logits. Was this intended?\n",
      "  output, from_logits = _get_logits(\n"
     ]
    },
    {
     "ename": "InvalidArgumentError",
     "evalue": "Graph execution error:\n\nDetected at node 'sparse_categorical_crossentropy/SparseSoftmaxCrossEntropyWithLogits/SparseSoftmaxCrossEntropyWithLogits' defined at (most recent call last):\n    File \"C:\\ProgramData\\Anaconda3\\lib\\runpy.py\", line 197, in _run_module_as_main\n      return _run_code(code, main_globals, None,\n    File \"C:\\ProgramData\\Anaconda3\\lib\\runpy.py\", line 87, in _run_code\n      exec(code, run_globals)\n    File \"C:\\ProgramData\\Anaconda3\\lib\\site-packages\\ipykernel_launcher.py\", line 17, in <module>\n      app.launch_new_instance()\n    File \"C:\\ProgramData\\Anaconda3\\lib\\site-packages\\traitlets\\config\\application.py\", line 992, in launch_instance\n      app.start()\n    File \"C:\\ProgramData\\Anaconda3\\lib\\site-packages\\ipykernel\\kernelapp.py\", line 711, in start\n      self.io_loop.start()\n    File \"C:\\ProgramData\\Anaconda3\\lib\\site-packages\\tornado\\platform\\asyncio.py\", line 215, in start\n      self.asyncio_loop.run_forever()\n    File \"C:\\ProgramData\\Anaconda3\\lib\\asyncio\\base_events.py\", line 601, in run_forever\n      self._run_once()\n    File \"C:\\ProgramData\\Anaconda3\\lib\\asyncio\\base_events.py\", line 1905, in _run_once\n      handle._run()\n    File \"C:\\ProgramData\\Anaconda3\\lib\\asyncio\\events.py\", line 80, in _run\n      self._context.run(self._callback, *self._args)\n    File \"C:\\ProgramData\\Anaconda3\\lib\\site-packages\\ipykernel\\kernelbase.py\", line 510, in dispatch_queue\n      await self.process_one()\n    File \"C:\\ProgramData\\Anaconda3\\lib\\site-packages\\ipykernel\\kernelbase.py\", line 499, in process_one\n      await dispatch(*args)\n    File \"C:\\ProgramData\\Anaconda3\\lib\\site-packages\\ipykernel\\kernelbase.py\", line 406, in dispatch_shell\n      await result\n    File \"C:\\ProgramData\\Anaconda3\\lib\\site-packages\\ipykernel\\kernelbase.py\", line 729, in execute_request\n      reply_content = await reply_content\n    File \"C:\\ProgramData\\Anaconda3\\lib\\site-packages\\ipykernel\\ipkernel.py\", line 411, in do_execute\n      res = shell.run_cell(\n    File \"C:\\ProgramData\\Anaconda3\\lib\\site-packages\\ipykernel\\zmqshell.py\", line 531, in run_cell\n      return super().run_cell(*args, **kwargs)\n    File \"C:\\ProgramData\\Anaconda3\\lib\\site-packages\\IPython\\core\\interactiveshell.py\", line 3006, in run_cell\n      result = self._run_cell(\n    File \"C:\\ProgramData\\Anaconda3\\lib\\site-packages\\IPython\\core\\interactiveshell.py\", line 3061, in _run_cell\n      result = runner(coro)\n    File \"C:\\ProgramData\\Anaconda3\\lib\\site-packages\\IPython\\core\\async_helpers.py\", line 129, in _pseudo_sync_runner\n      coro.send(None)\n    File \"C:\\ProgramData\\Anaconda3\\lib\\site-packages\\IPython\\core\\interactiveshell.py\", line 3266, in run_cell_async\n      has_raised = await self.run_ast_nodes(code_ast.body, cell_name,\n    File \"C:\\ProgramData\\Anaconda3\\lib\\site-packages\\IPython\\core\\interactiveshell.py\", line 3445, in run_ast_nodes\n      if await self.run_code(code, result, async_=asy):\n    File \"C:\\ProgramData\\Anaconda3\\lib\\site-packages\\IPython\\core\\interactiveshell.py\", line 3505, in run_code\n      exec(code_obj, self.user_global_ns, self.user_ns)\n    File \"C:\\Users\\Progra\\AppData\\Local\\Temp\\ipykernel_12132\\1334670808.py\", line 1, in <module>\n      puntuaciones_aprendizaje = modelo.evaluate(X_prueba, y_prueba)\n    File \"C:\\Users\\Progra\\AppData\\Roaming\\Python\\Python39\\site-packages\\keras\\utils\\traceback_utils.py\", line 65, in error_handler\n      return fn(*args, **kwargs)\n    File \"C:\\Users\\Progra\\AppData\\Roaming\\Python\\Python39\\site-packages\\keras\\engine\\training.py\", line 2072, in evaluate\n      tmp_logs = self.test_function(iterator)\n    File \"C:\\Users\\Progra\\AppData\\Roaming\\Python\\Python39\\site-packages\\keras\\engine\\training.py\", line 1852, in test_function\n      return step_function(self, iterator)\n    File \"C:\\Users\\Progra\\AppData\\Roaming\\Python\\Python39\\site-packages\\keras\\engine\\training.py\", line 1836, in step_function\n      outputs = model.distribute_strategy.run(run_step, args=(data,))\n    File \"C:\\Users\\Progra\\AppData\\Roaming\\Python\\Python39\\site-packages\\keras\\engine\\training.py\", line 1824, in run_step\n      outputs = model.test_step(data)\n    File \"C:\\Users\\Progra\\AppData\\Roaming\\Python\\Python39\\site-packages\\keras\\engine\\training.py\", line 1790, in test_step\n      self.compute_loss(x, y, y_pred, sample_weight)\n    File \"C:\\Users\\Progra\\AppData\\Roaming\\Python\\Python39\\site-packages\\keras\\engine\\training.py\", line 1109, in compute_loss\n      return self.compiled_loss(\n    File \"C:\\Users\\Progra\\AppData\\Roaming\\Python\\Python39\\site-packages\\keras\\engine\\compile_utils.py\", line 265, in __call__\n      loss_value = loss_obj(y_t, y_p, sample_weight=sw)\n    File \"C:\\Users\\Progra\\AppData\\Roaming\\Python\\Python39\\site-packages\\keras\\losses.py\", line 142, in __call__\n      losses = call_fn(y_true, y_pred)\n    File \"C:\\Users\\Progra\\AppData\\Roaming\\Python\\Python39\\site-packages\\keras\\losses.py\", line 268, in call\n      return ag_fn(y_true, y_pred, **self._fn_kwargs)\n    File \"C:\\Users\\Progra\\AppData\\Roaming\\Python\\Python39\\site-packages\\keras\\losses.py\", line 2078, in sparse_categorical_crossentropy\n      return backend.sparse_categorical_crossentropy(\n    File \"C:\\Users\\Progra\\AppData\\Roaming\\Python\\Python39\\site-packages\\keras\\backend.py\", line 5660, in sparse_categorical_crossentropy\n      res = tf.nn.sparse_softmax_cross_entropy_with_logits(\nNode: 'sparse_categorical_crossentropy/SparseSoftmaxCrossEntropyWithLogits/SparseSoftmaxCrossEntropyWithLogits'\nReceived a label value of 1144 which is outside the valid range of [0, 3).  Label values: 274 30 22 915 16 326 72 6 1144 208 65 130 52 45 35 36 51 31 100 132 50 60 111 18 11 50 69 27 19 41 248 32\n\t [[{{node sparse_categorical_crossentropy/SparseSoftmaxCrossEntropyWithLogits/SparseSoftmaxCrossEntropyWithLogits}}]] [Op:__inference_test_function_7665]",
     "output_type": "error",
     "traceback": [
      "\u001b[1;31m---------------------------------------------------------------------------\u001b[0m",
      "\u001b[1;31mInvalidArgumentError\u001b[0m                      Traceback (most recent call last)",
      "Cell \u001b[1;32mIn[60], line 1\u001b[0m\n\u001b[1;32m----> 1\u001b[0m puntuaciones_aprendizaje \u001b[38;5;241m=\u001b[39m \u001b[43mmodelo\u001b[49m\u001b[38;5;241;43m.\u001b[39;49m\u001b[43mevaluate\u001b[49m\u001b[43m(\u001b[49m\u001b[43mX_prueba\u001b[49m\u001b[43m,\u001b[49m\u001b[43m \u001b[49m\u001b[43my_prueba\u001b[49m\u001b[43m)\u001b[49m\n\u001b[0;32m      2\u001b[0m mediana_puntuaciones \u001b[38;5;241m=\u001b[39m median(puntuaciones_aprendizaje)\n",
      "File \u001b[1;32m~\\AppData\\Roaming\\Python\\Python39\\site-packages\\keras\\utils\\traceback_utils.py:70\u001b[0m, in \u001b[0;36mfilter_traceback.<locals>.error_handler\u001b[1;34m(*args, **kwargs)\u001b[0m\n\u001b[0;32m     67\u001b[0m     filtered_tb \u001b[38;5;241m=\u001b[39m _process_traceback_frames(e\u001b[38;5;241m.\u001b[39m__traceback__)\n\u001b[0;32m     68\u001b[0m     \u001b[38;5;66;03m# To get the full stack trace, call:\u001b[39;00m\n\u001b[0;32m     69\u001b[0m     \u001b[38;5;66;03m# `tf.debugging.disable_traceback_filtering()`\u001b[39;00m\n\u001b[1;32m---> 70\u001b[0m     \u001b[38;5;28;01mraise\u001b[39;00m e\u001b[38;5;241m.\u001b[39mwith_traceback(filtered_tb) \u001b[38;5;28;01mfrom\u001b[39;00m \u001b[38;5;28;01mNone\u001b[39;00m\n\u001b[0;32m     71\u001b[0m \u001b[38;5;28;01mfinally\u001b[39;00m:\n\u001b[0;32m     72\u001b[0m     \u001b[38;5;28;01mdel\u001b[39;00m filtered_tb\n",
      "File \u001b[1;32m~\\AppData\\Roaming\\Python\\Python39\\site-packages\\tensorflow\\python\\eager\\execute.py:52\u001b[0m, in \u001b[0;36mquick_execute\u001b[1;34m(op_name, num_outputs, inputs, attrs, ctx, name)\u001b[0m\n\u001b[0;32m     50\u001b[0m \u001b[38;5;28;01mtry\u001b[39;00m:\n\u001b[0;32m     51\u001b[0m   ctx\u001b[38;5;241m.\u001b[39mensure_initialized()\n\u001b[1;32m---> 52\u001b[0m   tensors \u001b[38;5;241m=\u001b[39m pywrap_tfe\u001b[38;5;241m.\u001b[39mTFE_Py_Execute(ctx\u001b[38;5;241m.\u001b[39m_handle, device_name, op_name,\n\u001b[0;32m     53\u001b[0m                                       inputs, attrs, num_outputs)\n\u001b[0;32m     54\u001b[0m \u001b[38;5;28;01mexcept\u001b[39;00m core\u001b[38;5;241m.\u001b[39m_NotOkStatusException \u001b[38;5;28;01mas\u001b[39;00m e:\n\u001b[0;32m     55\u001b[0m   \u001b[38;5;28;01mif\u001b[39;00m name \u001b[38;5;129;01mis\u001b[39;00m \u001b[38;5;129;01mnot\u001b[39;00m \u001b[38;5;28;01mNone\u001b[39;00m:\n",
      "\u001b[1;31mInvalidArgumentError\u001b[0m: Graph execution error:\n\nDetected at node 'sparse_categorical_crossentropy/SparseSoftmaxCrossEntropyWithLogits/SparseSoftmaxCrossEntropyWithLogits' defined at (most recent call last):\n    File \"C:\\ProgramData\\Anaconda3\\lib\\runpy.py\", line 197, in _run_module_as_main\n      return _run_code(code, main_globals, None,\n    File \"C:\\ProgramData\\Anaconda3\\lib\\runpy.py\", line 87, in _run_code\n      exec(code, run_globals)\n    File \"C:\\ProgramData\\Anaconda3\\lib\\site-packages\\ipykernel_launcher.py\", line 17, in <module>\n      app.launch_new_instance()\n    File \"C:\\ProgramData\\Anaconda3\\lib\\site-packages\\traitlets\\config\\application.py\", line 992, in launch_instance\n      app.start()\n    File \"C:\\ProgramData\\Anaconda3\\lib\\site-packages\\ipykernel\\kernelapp.py\", line 711, in start\n      self.io_loop.start()\n    File \"C:\\ProgramData\\Anaconda3\\lib\\site-packages\\tornado\\platform\\asyncio.py\", line 215, in start\n      self.asyncio_loop.run_forever()\n    File \"C:\\ProgramData\\Anaconda3\\lib\\asyncio\\base_events.py\", line 601, in run_forever\n      self._run_once()\n    File \"C:\\ProgramData\\Anaconda3\\lib\\asyncio\\base_events.py\", line 1905, in _run_once\n      handle._run()\n    File \"C:\\ProgramData\\Anaconda3\\lib\\asyncio\\events.py\", line 80, in _run\n      self._context.run(self._callback, *self._args)\n    File \"C:\\ProgramData\\Anaconda3\\lib\\site-packages\\ipykernel\\kernelbase.py\", line 510, in dispatch_queue\n      await self.process_one()\n    File \"C:\\ProgramData\\Anaconda3\\lib\\site-packages\\ipykernel\\kernelbase.py\", line 499, in process_one\n      await dispatch(*args)\n    File \"C:\\ProgramData\\Anaconda3\\lib\\site-packages\\ipykernel\\kernelbase.py\", line 406, in dispatch_shell\n      await result\n    File \"C:\\ProgramData\\Anaconda3\\lib\\site-packages\\ipykernel\\kernelbase.py\", line 729, in execute_request\n      reply_content = await reply_content\n    File \"C:\\ProgramData\\Anaconda3\\lib\\site-packages\\ipykernel\\ipkernel.py\", line 411, in do_execute\n      res = shell.run_cell(\n    File \"C:\\ProgramData\\Anaconda3\\lib\\site-packages\\ipykernel\\zmqshell.py\", line 531, in run_cell\n      return super().run_cell(*args, **kwargs)\n    File \"C:\\ProgramData\\Anaconda3\\lib\\site-packages\\IPython\\core\\interactiveshell.py\", line 3006, in run_cell\n      result = self._run_cell(\n    File \"C:\\ProgramData\\Anaconda3\\lib\\site-packages\\IPython\\core\\interactiveshell.py\", line 3061, in _run_cell\n      result = runner(coro)\n    File \"C:\\ProgramData\\Anaconda3\\lib\\site-packages\\IPython\\core\\async_helpers.py\", line 129, in _pseudo_sync_runner\n      coro.send(None)\n    File \"C:\\ProgramData\\Anaconda3\\lib\\site-packages\\IPython\\core\\interactiveshell.py\", line 3266, in run_cell_async\n      has_raised = await self.run_ast_nodes(code_ast.body, cell_name,\n    File \"C:\\ProgramData\\Anaconda3\\lib\\site-packages\\IPython\\core\\interactiveshell.py\", line 3445, in run_ast_nodes\n      if await self.run_code(code, result, async_=asy):\n    File \"C:\\ProgramData\\Anaconda3\\lib\\site-packages\\IPython\\core\\interactiveshell.py\", line 3505, in run_code\n      exec(code_obj, self.user_global_ns, self.user_ns)\n    File \"C:\\Users\\Progra\\AppData\\Local\\Temp\\ipykernel_12132\\1334670808.py\", line 1, in <module>\n      puntuaciones_aprendizaje = modelo.evaluate(X_prueba, y_prueba)\n    File \"C:\\Users\\Progra\\AppData\\Roaming\\Python\\Python39\\site-packages\\keras\\utils\\traceback_utils.py\", line 65, in error_handler\n      return fn(*args, **kwargs)\n    File \"C:\\Users\\Progra\\AppData\\Roaming\\Python\\Python39\\site-packages\\keras\\engine\\training.py\", line 2072, in evaluate\n      tmp_logs = self.test_function(iterator)\n    File \"C:\\Users\\Progra\\AppData\\Roaming\\Python\\Python39\\site-packages\\keras\\engine\\training.py\", line 1852, in test_function\n      return step_function(self, iterator)\n    File \"C:\\Users\\Progra\\AppData\\Roaming\\Python\\Python39\\site-packages\\keras\\engine\\training.py\", line 1836, in step_function\n      outputs = model.distribute_strategy.run(run_step, args=(data,))\n    File \"C:\\Users\\Progra\\AppData\\Roaming\\Python\\Python39\\site-packages\\keras\\engine\\training.py\", line 1824, in run_step\n      outputs = model.test_step(data)\n    File \"C:\\Users\\Progra\\AppData\\Roaming\\Python\\Python39\\site-packages\\keras\\engine\\training.py\", line 1790, in test_step\n      self.compute_loss(x, y, y_pred, sample_weight)\n    File \"C:\\Users\\Progra\\AppData\\Roaming\\Python\\Python39\\site-packages\\keras\\engine\\training.py\", line 1109, in compute_loss\n      return self.compiled_loss(\n    File \"C:\\Users\\Progra\\AppData\\Roaming\\Python\\Python39\\site-packages\\keras\\engine\\compile_utils.py\", line 265, in __call__\n      loss_value = loss_obj(y_t, y_p, sample_weight=sw)\n    File \"C:\\Users\\Progra\\AppData\\Roaming\\Python\\Python39\\site-packages\\keras\\losses.py\", line 142, in __call__\n      losses = call_fn(y_true, y_pred)\n    File \"C:\\Users\\Progra\\AppData\\Roaming\\Python\\Python39\\site-packages\\keras\\losses.py\", line 268, in call\n      return ag_fn(y_true, y_pred, **self._fn_kwargs)\n    File \"C:\\Users\\Progra\\AppData\\Roaming\\Python\\Python39\\site-packages\\keras\\losses.py\", line 2078, in sparse_categorical_crossentropy\n      return backend.sparse_categorical_crossentropy(\n    File \"C:\\Users\\Progra\\AppData\\Roaming\\Python\\Python39\\site-packages\\keras\\backend.py\", line 5660, in sparse_categorical_crossentropy\n      res = tf.nn.sparse_softmax_cross_entropy_with_logits(\nNode: 'sparse_categorical_crossentropy/SparseSoftmaxCrossEntropyWithLogits/SparseSoftmaxCrossEntropyWithLogits'\nReceived a label value of 1144 which is outside the valid range of [0, 3).  Label values: 274 30 22 915 16 326 72 6 1144 208 65 130 52 45 35 36 51 31 100 132 50 60 111 18 11 50 69 27 19 41 248 32\n\t [[{{node sparse_categorical_crossentropy/SparseSoftmaxCrossEntropyWithLogits/SparseSoftmaxCrossEntropyWithLogits}}]] [Op:__inference_test_function_7665]"
     ]
    }
   ],
   "source": [
    "puntuaciones_aprendizaje = modelo.evaluate(X_prueba, y_prueba)\n",
    "mediana_puntuaciones = median(puntuaciones_aprendizaje)\n"
   ]
  },
  {
   "cell_type": "code",
   "execution_count": null,
   "id": "b91fb5ca",
   "metadata": {},
   "outputs": [],
   "source": []
  }
 ],
 "metadata": {
  "kernelspec": {
   "display_name": "Python 3 (ipykernel)",
   "language": "python",
   "name": "python3"
  },
  "language_info": {
   "codemirror_mode": {
    "name": "ipython",
    "version": 3
   },
   "file_extension": ".py",
   "mimetype": "text/x-python",
   "name": "python",
   "nbconvert_exporter": "python",
   "pygments_lexer": "ipython3",
   "version": "3.9.16"
  }
 },
 "nbformat": 4,
 "nbformat_minor": 5
}
